[2024-06-24T18:37:42.715+0000] {local_task_job_runner.py:120} INFO - ::group::Pre task execution logs
[2024-06-24T18:37:42.734+0000] {taskinstance.py:2076} INFO - Dependencies all met for dep_context=non-requeueable deps ti=<TaskInstance: dag_with_postgres_operator_v01.create_postgres_table manual__2024-06-23T17:14:26.469362+00:00 [queued]>
[2024-06-24T18:37:42.737+0000] {taskinstance.py:2076} INFO - Dependencies all met for dep_context=requeueable deps ti=<TaskInstance: dag_with_postgres_operator_v01.create_postgres_table manual__2024-06-23T17:14:26.469362+00:00 [queued]>
[2024-06-24T18:37:42.737+0000] {taskinstance.py:2306} INFO - Starting attempt 4 of 6
[2024-06-24T18:37:42.742+0000] {taskinstance.py:2330} INFO - Executing <Task(PostgresOperator): create_postgres_table> on 2024-06-23 17:14:26.469362+00:00
[2024-06-24T18:37:42.745+0000] {standard_task_runner.py:90} INFO - Running: ['***', 'tasks', 'run', 'dag_with_postgres_operator_v01', 'create_postgres_table', 'manual__2024-06-23T17:14:26.469362+00:00', '--job-id', '8', '--raw', '--subdir', 'DAGS_FOLDER/postgres_dag.py', '--cfg-path', '/tmp/tmp50vbu85o']
[2024-06-24T18:37:42.747+0000] {logging_mixin.py:188} WARNING - /home/***/.local/lib/python3.12/site-packages/***/task/task_runner/standard_task_runner.py:61 DeprecationWarning: This process (pid=392) is multi-threaded, use of fork() may lead to deadlocks in the child.
[2024-06-24T18:37:42.747+0000] {standard_task_runner.py:91} INFO - Job 8: Subtask create_postgres_table
[2024-06-24T18:37:42.747+0000] {standard_task_runner.py:63} INFO - Started process 393 to run task
[2024-06-24T18:37:42.771+0000] {task_command.py:426} INFO - Running <TaskInstance: dag_with_postgres_operator_v01.create_postgres_table manual__2024-06-23T17:14:26.469362+00:00 [running]> on host 3b316f897547
[2024-06-24T18:37:42.807+0000] {taskinstance.py:2648} INFO - Exporting env vars: AIRFLOW_CTX_DAG_OWNER='jack' AIRFLOW_CTX_DAG_ID='dag_with_postgres_operator_v01' AIRFLOW_CTX_TASK_ID='create_postgres_table' AIRFLOW_CTX_EXECUTION_DATE='2024-06-23T17:14:26.469362+00:00' AIRFLOW_CTX_TRY_NUMBER='4' AIRFLOW_CTX_DAG_RUN_ID='manual__2024-06-23T17:14:26.469362+00:00'
[2024-06-24T18:37:42.808+0000] {taskinstance.py:430} INFO - ::endgroup::
[2024-06-24T18:37:42.816+0000] {sql.py:276} INFO - Executing: 

        
[2024-06-24T18:37:42.820+0000] {taskinstance.py:441} INFO - ::group::Post task execution logs
[2024-06-24T18:37:42.824+0000] {taskinstance.py:2905} ERROR - Task failed with exception
Traceback (most recent call last):
  File "/home/airflow/.local/lib/python3.12/site-packages/airflow/models/taskinstance.py", line 465, in _execute_task
    result = _execute_callable(context=context, **execute_callable_kwargs)
             ^^^^^^^^^^^^^^^^^^^^^^^^^^^^^^^^^^^^^^^^^^^^^^^^^^^^^^^^^^^^^
  File "/home/airflow/.local/lib/python3.12/site-packages/airflow/models/taskinstance.py", line 432, in _execute_callable
    return execute_callable(context=context, **execute_callable_kwargs)
           ^^^^^^^^^^^^^^^^^^^^^^^^^^^^^^^^^^^^^^^^^^^^^^^^^^^^^^^^^^^^
  File "/home/airflow/.local/lib/python3.12/site-packages/airflow/models/baseoperator.py", line 401, in wrapper
    return func(self, *args, **kwargs)
           ^^^^^^^^^^^^^^^^^^^^^^^^^^^
  File "/home/airflow/.local/lib/python3.12/site-packages/airflow/providers/common/sql/operators/sql.py", line 277, in execute
    hook = self.get_db_hook()
           ^^^^^^^^^^^^^^^^^^
  File "/home/airflow/.local/lib/python3.12/site-packages/airflow/providers/common/sql/operators/sql.py", line 188, in get_db_hook
    return self._hook
           ^^^^^^^^^^
  File "/usr/local/lib/python3.12/functools.py", line 995, in __get__
    val = self.func(instance)
          ^^^^^^^^^^^^^^^^^^^
  File "/home/airflow/.local/lib/python3.12/site-packages/airflow/providers/common/sql/operators/sql.py", line 150, in _hook
    conn = BaseHook.get_connection(conn_id)
           ^^^^^^^^^^^^^^^^^^^^^^^^^^^^^^^^
  File "/home/airflow/.local/lib/python3.12/site-packages/airflow/hooks/base.py", line 83, in get_connection
    conn = Connection.get_connection_from_secrets(conn_id)
           ^^^^^^^^^^^^^^^^^^^^^^^^^^^^^^^^^^^^^^^^^^^^^^^
  File "/home/airflow/.local/lib/python3.12/site-packages/airflow/models/connection.py", line 519, in get_connection_from_secrets
    raise AirflowNotFoundException(f"The conn_id `{conn_id}` isn't defined")
airflow.exceptions.AirflowNotFoundException: The conn_id `postgres_localhost` isn't defined
[2024-06-24T18:37:42.826+0000] {taskinstance.py:1206} INFO - Marking task as UP_FOR_RETRY. dag_id=dag_with_postgres_operator_v01, task_id=create_postgres_table, run_id=manual__2024-06-23T17:14:26.469362+00:00, execution_date=20240623T171426, start_date=20240624T183742, end_date=20240624T183742
[2024-06-24T18:37:42.830+0000] {standard_task_runner.py:110} ERROR - Failed to execute job 8 for task create_postgres_table (The conn_id `postgres_localhost` isn't defined; 393)
[2024-06-24T18:37:42.848+0000] {local_task_job_runner.py:240} INFO - Task exited with return code 1
[2024-06-24T18:37:42.856+0000] {taskinstance.py:3503} INFO - 0 downstream tasks scheduled from follow-on schedule check
[2024-06-24T18:37:42.856+0000] {local_task_job_runner.py:222} INFO - ::endgroup::
