[2024-08-11T10:14:20.107+0000] {local_task_job_runner.py:120} INFO - ::group::Pre task execution logs
[2024-08-11T10:14:20.130+0000] {taskinstance.py:2076} INFO - Dependencies all met for dep_context=non-requeueable deps ti=<TaskInstance: dag_with_postgres_operator_v01.create_postgres_table scheduled__2024-07-01T00:00:00+00:00 [queued]>
[2024-08-11T10:14:20.134+0000] {taskinstance.py:2076} INFO - Dependencies all met for dep_context=requeueable deps ti=<TaskInstance: dag_with_postgres_operator_v01.create_postgres_table scheduled__2024-07-01T00:00:00+00:00 [queued]>
[2024-08-11T10:14:20.135+0000] {taskinstance.py:2306} INFO - Starting attempt 5 of 6
[2024-08-11T10:14:20.146+0000] {taskinstance.py:2330} INFO - Executing <Task(PostgresOperator): create_postgres_table> on 2024-07-01 00:00:00+00:00
[2024-08-11T10:14:20.152+0000] {standard_task_runner.py:90} INFO - Running: ['***', 'tasks', 'run', 'dag_with_postgres_operator_v01', 'create_postgres_table', 'scheduled__2024-07-01T00:00:00+00:00', '--job-id', '71', '--raw', '--subdir', 'DAGS_FOLDER/postgres_dag.py', '--cfg-path', '/tmp/tmp8q8_ywr8']
[2024-08-11T10:14:20.153+0000] {logging_mixin.py:188} WARNING - /home/***/.local/lib/python3.12/site-packages/***/task/task_runner/standard_task_runner.py:61 DeprecationWarning: This process (pid=879) is multi-threaded, use of fork() may lead to deadlocks in the child.
[2024-08-11T10:14:20.154+0000] {standard_task_runner.py:91} INFO - Job 71: Subtask create_postgres_table
[2024-08-11T10:14:20.154+0000] {standard_task_runner.py:63} INFO - Started process 885 to run task
[2024-08-11T10:14:20.188+0000] {task_command.py:426} INFO - Running <TaskInstance: dag_with_postgres_operator_v01.create_postgres_table scheduled__2024-07-01T00:00:00+00:00 [running]> on host 3b316f897547
[2024-08-11T10:14:20.238+0000] {taskinstance.py:2648} INFO - Exporting env vars: AIRFLOW_CTX_DAG_OWNER='jack' AIRFLOW_CTX_DAG_ID='dag_with_postgres_operator_v01' AIRFLOW_CTX_TASK_ID='create_postgres_table' AIRFLOW_CTX_EXECUTION_DATE='2024-07-01T00:00:00+00:00' AIRFLOW_CTX_TRY_NUMBER='5' AIRFLOW_CTX_DAG_RUN_ID='scheduled__2024-07-01T00:00:00+00:00'
[2024-08-11T10:14:20.239+0000] {taskinstance.py:430} INFO - ::endgroup::
[2024-08-11T10:14:20.247+0000] {sql.py:276} INFO - Executing: 
            CREATE SCHEMA IF NOT EXISTS customer_schema;

            DROP TABLE IF EXISTS customer_schema.customer_table;

            CREATE TABLE customer_schema.customer_table (
                InvoiceNo TEXT,
                StockCode TEXT,
                "Description" TEXT,
                Quantity INT,
                InvoiceDate TIMESTAMP,
                UnitPrice FLOAT,
                CustomerID TEXT,
                Country TEXT
            );
             
[2024-08-11T10:14:20.255+0000] {base.py:84} INFO - Using connection ID 'postgres_localhost' for task execution.
[2024-08-11T10:14:20.263+0000] {base.py:84} INFO - Using connection ID 'postgres_localhost' for task execution.
[2024-08-11T10:14:20.274+0000] {taskinstance.py:441} INFO - ::group::Post task execution logs
[2024-08-11T10:14:20.275+0000] {taskinstance.py:2905} ERROR - Task failed with exception
Traceback (most recent call last):
  File "/home/airflow/.local/lib/python3.12/site-packages/airflow/models/taskinstance.py", line 465, in _execute_task
    result = _execute_callable(context=context, **execute_callable_kwargs)
             ^^^^^^^^^^^^^^^^^^^^^^^^^^^^^^^^^^^^^^^^^^^^^^^^^^^^^^^^^^^^^
  File "/home/airflow/.local/lib/python3.12/site-packages/airflow/models/taskinstance.py", line 432, in _execute_callable
    return execute_callable(context=context, **execute_callable_kwargs)
           ^^^^^^^^^^^^^^^^^^^^^^^^^^^^^^^^^^^^^^^^^^^^^^^^^^^^^^^^^^^^
  File "/home/airflow/.local/lib/python3.12/site-packages/airflow/models/baseoperator.py", line 401, in wrapper
    return func(self, *args, **kwargs)
           ^^^^^^^^^^^^^^^^^^^^^^^^^^^
  File "/home/airflow/.local/lib/python3.12/site-packages/airflow/providers/common/sql/operators/sql.py", line 282, in execute
    output = hook.run(
             ^^^^^^^^^
  File "/home/airflow/.local/lib/python3.12/site-packages/airflow/providers/common/sql/hooks/sql.py", line 431, in run
    with self._create_autocommit_connection(autocommit) as conn:
  File "/usr/local/lib/python3.12/contextlib.py", line 137, in __enter__
    return next(self.gen)
           ^^^^^^^^^^^^^^
  File "/home/airflow/.local/lib/python3.12/site-packages/airflow/providers/common/sql/hooks/sql.py", line 551, in _create_autocommit_connection
    with closing(self.get_conn()) as conn:
                 ^^^^^^^^^^^^^^^
  File "/home/airflow/.local/lib/python3.12/site-packages/airflow/providers/postgres/hooks/postgres.py", line 175, in get_conn
    self.conn = psycopg2.connect(**conn_args)
                ^^^^^^^^^^^^^^^^^^^^^^^^^^^^^
  File "/home/airflow/.local/lib/python3.12/site-packages/psycopg2/__init__.py", line 122, in connect
    conn = _connect(dsn, connection_factory=connection_factory, **kwasync)
           ^^^^^^^^^^^^^^^^^^^^^^^^^^^^^^^^^^^^^^^^^^^^^^^^^^^^^^^^^^^^^^^
psycopg2.OperationalError: connection to server at "host.docker.internal" (192.168.65.254), port 5432 failed: FATAL:  password authentication failed for user "***"

[2024-08-11T10:14:20.281+0000] {taskinstance.py:1206} INFO - Marking task as UP_FOR_RETRY. dag_id=dag_with_postgres_operator_v01, task_id=create_postgres_table, run_id=scheduled__2024-07-01T00:00:00+00:00, execution_date=20240701T000000, start_date=20240811T101420, end_date=20240811T101420
[2024-08-11T10:14:20.287+0000] {standard_task_runner.py:110} ERROR - Failed to execute job 71 for task create_postgres_table (connection to server at "host.docker.internal" (192.168.65.254), port 5432 failed: FATAL:  password authentication failed for user "***"
; 885)
[2024-08-11T10:14:20.300+0000] {local_task_job_runner.py:240} INFO - Task exited with return code 1
[2024-08-11T10:14:20.306+0000] {local_task_job_runner.py:222} INFO - ::endgroup::
