[2024-09-24T03:26:34.905+0000] {local_task_job_runner.py:120} INFO - ::group::Pre task execution logs
[2024-09-24T03:26:34.930+0000] {taskinstance.py:2076} INFO - Dependencies all met for dep_context=non-requeueable deps ti=<TaskInstance: dag_with_postgres_operator_v01.insert_into_table manual__2024-09-24T03:21:33.200381+00:00 [queued]>
[2024-09-24T03:26:34.935+0000] {taskinstance.py:2076} INFO - Dependencies all met for dep_context=requeueable deps ti=<TaskInstance: dag_with_postgres_operator_v01.insert_into_table manual__2024-09-24T03:21:33.200381+00:00 [queued]>
[2024-09-24T03:26:34.936+0000] {taskinstance.py:2306} INFO - Starting attempt 2 of 6
[2024-09-24T03:26:34.944+0000] {taskinstance.py:2330} INFO - Executing <Task(PostgresOperator): insert_into_table> on 2024-09-24 03:21:33.200381+00:00
[2024-09-24T03:26:34.949+0000] {standard_task_runner.py:90} INFO - Running: ['***', 'tasks', 'run', 'dag_with_postgres_operator_v01', 'insert_into_table', 'manual__2024-09-24T03:21:33.200381+00:00', '--job-id', '103', '--raw', '--subdir', 'DAGS_FOLDER/postgres_dag.py', '--cfg-path', '/tmp/tmpaj3kvstm']
[2024-09-24T03:26:34.951+0000] {standard_task_runner.py:91} INFO - Job 103: Subtask insert_into_table
[2024-09-24T03:26:34.951+0000] {logging_mixin.py:188} WARNING - /home/***/.local/lib/python3.12/site-packages/***/task/task_runner/standard_task_runner.py:61 DeprecationWarning: This process (pid=601) is multi-threaded, use of fork() may lead to deadlocks in the child.
[2024-09-24T03:26:34.951+0000] {standard_task_runner.py:63} INFO - Started process 602 to run task
[2024-09-24T03:26:34.982+0000] {task_command.py:426} INFO - Running <TaskInstance: dag_with_postgres_operator_v01.insert_into_table manual__2024-09-24T03:21:33.200381+00:00 [running]> on host 4112e4e10001
[2024-09-24T03:26:35.044+0000] {taskinstance.py:2648} INFO - Exporting env vars: AIRFLOW_CTX_DAG_OWNER='jack' AIRFLOW_CTX_DAG_ID='dag_with_postgres_operator_v01' AIRFLOW_CTX_TASK_ID='insert_into_table' AIRFLOW_CTX_EXECUTION_DATE='2024-09-24T03:21:33.200381+00:00' AIRFLOW_CTX_TRY_NUMBER='2' AIRFLOW_CTX_DAG_RUN_ID='manual__2024-09-24T03:21:33.200381+00:00'
[2024-09-24T03:26:35.044+0000] {taskinstance.py:430} INFO - ::endgroup::
[2024-09-24T03:26:35.057+0000] {sql.py:276} INFO - Executing: 
            insert into Orders values(1,'pending')
        
[2024-09-24T03:26:35.064+0000] {base.py:84} INFO - Using connection ID 'postgres_localhost' for task execution.
[2024-09-24T03:26:35.072+0000] {base.py:84} INFO - Using connection ID 'postgres_localhost' for task execution.
[2024-09-24T03:26:35.080+0000] {sql.py:487} INFO - Running statement: 
            insert into Orders values(1,'pending')
        , parameters: None
[2024-09-24T03:26:35.081+0000] {taskinstance.py:441} INFO - ::group::Post task execution logs
[2024-09-24T03:26:35.082+0000] {taskinstance.py:2905} ERROR - Task failed with exception
Traceback (most recent call last):
  File "/home/airflow/.local/lib/python3.12/site-packages/airflow/models/taskinstance.py", line 465, in _execute_task
    result = _execute_callable(context=context, **execute_callable_kwargs)
             ^^^^^^^^^^^^^^^^^^^^^^^^^^^^^^^^^^^^^^^^^^^^^^^^^^^^^^^^^^^^^
  File "/home/airflow/.local/lib/python3.12/site-packages/airflow/models/taskinstance.py", line 432, in _execute_callable
    return execute_callable(context=context, **execute_callable_kwargs)
           ^^^^^^^^^^^^^^^^^^^^^^^^^^^^^^^^^^^^^^^^^^^^^^^^^^^^^^^^^^^^
  File "/home/airflow/.local/lib/python3.12/site-packages/airflow/models/baseoperator.py", line 401, in wrapper
    return func(self, *args, **kwargs)
           ^^^^^^^^^^^^^^^^^^^^^^^^^^^
  File "/home/airflow/.local/lib/python3.12/site-packages/airflow/providers/common/sql/operators/sql.py", line 282, in execute
    output = hook.run(
             ^^^^^^^^^
  File "/home/airflow/.local/lib/python3.12/site-packages/airflow/providers/common/sql/hooks/sql.py", line 435, in run
    self._run_command(cur, sql_statement, parameters)
  File "/home/airflow/.local/lib/python3.12/site-packages/airflow/providers/common/sql/hooks/sql.py", line 492, in _run_command
    cur.execute(sql_statement)
psycopg2.errors.UndefinedTable: relation "orders" does not exist
LINE 2:             insert into Orders values(1,'pending')
                                ^

[2024-09-24T03:26:35.090+0000] {taskinstance.py:1206} INFO - Marking task as UP_FOR_RETRY. dag_id=dag_with_postgres_operator_v01, task_id=insert_into_table, run_id=manual__2024-09-24T03:21:33.200381+00:00, execution_date=20240924T032133, start_date=20240924T032634, end_date=20240924T032635
[2024-09-24T03:26:35.098+0000] {standard_task_runner.py:110} ERROR - Failed to execute job 103 for task insert_into_table (relation "orders" does not exist
LINE 2:             insert into Orders values(1,'pending')
                                ^
; 602)
[2024-09-24T03:26:35.136+0000] {local_task_job_runner.py:240} INFO - Task exited with return code 1
[2024-09-24T03:26:35.148+0000] {taskinstance.py:3503} INFO - 0 downstream tasks scheduled from follow-on schedule check
[2024-09-24T03:26:35.149+0000] {local_task_job_runner.py:222} INFO - ::endgroup::
