[2024-09-24T04:18:13.285+0000] {local_task_job_runner.py:120} INFO - ::group::Pre task execution logs
[2024-09-24T04:18:13.308+0000] {taskinstance.py:2076} INFO - Dependencies all met for dep_context=non-requeueable deps ti=<TaskInstance: dag_with_postgres_operator_v01.load_csv_to_postgres manual__2024-09-24T04:08:09.120319+00:00 [queued]>
[2024-09-24T04:18:13.313+0000] {taskinstance.py:2076} INFO - Dependencies all met for dep_context=requeueable deps ti=<TaskInstance: dag_with_postgres_operator_v01.load_csv_to_postgres manual__2024-09-24T04:08:09.120319+00:00 [queued]>
[2024-09-24T04:18:13.314+0000] {taskinstance.py:2306} INFO - Starting attempt 3 of 6
[2024-09-24T04:18:13.321+0000] {taskinstance.py:2330} INFO - Executing <Task(PythonOperator): load_csv_to_postgres> on 2024-09-24 04:08:09.120319+00:00
[2024-09-24T04:18:13.327+0000] {standard_task_runner.py:90} INFO - Running: ['***', 'tasks', 'run', 'dag_with_postgres_operator_v01', 'load_csv_to_postgres', 'manual__2024-09-24T04:08:09.120319+00:00', '--job-id', '112', '--raw', '--subdir', 'DAGS_FOLDER/postgres_dag.py', '--cfg-path', '/tmp/tmpj_s_izz_']
[2024-09-24T04:18:13.329+0000] {standard_task_runner.py:91} INFO - Job 112: Subtask load_csv_to_postgres
[2024-09-24T04:18:13.332+0000] {logging_mixin.py:188} WARNING - /home/***/.local/lib/python3.12/site-packages/***/task/task_runner/standard_task_runner.py:61 DeprecationWarning: This process (pid=682) is multi-threaded, use of fork() may lead to deadlocks in the child.
[2024-09-24T04:18:13.332+0000] {standard_task_runner.py:63} INFO - Started process 684 to run task
[2024-09-24T04:18:13.364+0000] {task_command.py:426} INFO - Running <TaskInstance: dag_with_postgres_operator_v01.load_csv_to_postgres manual__2024-09-24T04:08:09.120319+00:00 [running]> on host 4112e4e10001
[2024-09-24T04:18:13.572+0000] {taskinstance.py:2648} INFO - Exporting env vars: AIRFLOW_CTX_DAG_OWNER='jack' AIRFLOW_CTX_DAG_ID='dag_with_postgres_operator_v01' AIRFLOW_CTX_TASK_ID='load_csv_to_postgres' AIRFLOW_CTX_EXECUTION_DATE='2024-09-24T04:08:09.120319+00:00' AIRFLOW_CTX_TRY_NUMBER='3' AIRFLOW_CTX_DAG_RUN_ID='manual__2024-09-24T04:08:09.120319+00:00'
[2024-09-24T04:18:13.573+0000] {taskinstance.py:430} INFO - ::endgroup::
[2024-09-24T04:18:13.582+0000] {taskinstance.py:441} INFO - ::group::Post task execution logs
[2024-09-24T04:18:13.583+0000] {taskinstance.py:2905} ERROR - Task failed with exception
Traceback (most recent call last):
  File "/home/airflow/.local/lib/python3.12/site-packages/airflow/models/taskinstance.py", line 465, in _execute_task
    result = _execute_callable(context=context, **execute_callable_kwargs)
             ^^^^^^^^^^^^^^^^^^^^^^^^^^^^^^^^^^^^^^^^^^^^^^^^^^^^^^^^^^^^^
  File "/home/airflow/.local/lib/python3.12/site-packages/airflow/models/taskinstance.py", line 432, in _execute_callable
    return execute_callable(context=context, **execute_callable_kwargs)
           ^^^^^^^^^^^^^^^^^^^^^^^^^^^^^^^^^^^^^^^^^^^^^^^^^^^^^^^^^^^^
  File "/home/airflow/.local/lib/python3.12/site-packages/airflow/models/baseoperator.py", line 401, in wrapper
    return func(self, *args, **kwargs)
           ^^^^^^^^^^^^^^^^^^^^^^^^^^^
  File "/home/airflow/.local/lib/python3.12/site-packages/airflow/operators/python.py", line 235, in execute
    return_value = self.execute_callable()
                   ^^^^^^^^^^^^^^^^^^^^^^^
  File "/home/airflow/.local/lib/python3.12/site-packages/airflow/operators/python.py", line 252, in execute_callable
    return self.python_callable(*self.op_args, **self.op_kwargs)
           ^^^^^^^^^^^^^^^^^^^^^^^^^^^^^^^^^^^^^^^^^^^^^^^^^^^^^
  File "/opt/airflow/dags/postgres_dag.py", line 12, in load_csv_topostgress
    df = pd.read_csv(csv_file_path)
         ^^^^^^^^^^^^^^^^^^^^^^^^^^
  File "/home/airflow/.local/lib/python3.12/site-packages/pandas/io/parsers/readers.py", line 948, in read_csv
    return _read(filepath_or_buffer, kwds)
           ^^^^^^^^^^^^^^^^^^^^^^^^^^^^^^^
  File "/home/airflow/.local/lib/python3.12/site-packages/pandas/io/parsers/readers.py", line 611, in _read
    parser = TextFileReader(filepath_or_buffer, **kwds)
             ^^^^^^^^^^^^^^^^^^^^^^^^^^^^^^^^^^^^^^^^^^
  File "/home/airflow/.local/lib/python3.12/site-packages/pandas/io/parsers/readers.py", line 1448, in __init__
    self._engine = self._make_engine(f, self.engine)
                   ^^^^^^^^^^^^^^^^^^^^^^^^^^^^^^^^^
  File "/home/airflow/.local/lib/python3.12/site-packages/pandas/io/parsers/readers.py", line 1705, in _make_engine
    self.handles = get_handle(
                   ^^^^^^^^^^^
  File "/home/airflow/.local/lib/python3.12/site-packages/pandas/io/common.py", line 863, in get_handle
    handle = open(
             ^^^^^
FileNotFoundError: [Errno 2] No such file or directory: '/opt/data/retail_clean.csv'
[2024-09-24T04:18:13.591+0000] {taskinstance.py:1206} INFO - Marking task as UP_FOR_RETRY. dag_id=dag_with_postgres_operator_v01, task_id=load_csv_to_postgres, run_id=manual__2024-09-24T04:08:09.120319+00:00, execution_date=20240924T040809, start_date=20240924T041813, end_date=20240924T041813
[2024-09-24T04:18:13.600+0000] {standard_task_runner.py:110} ERROR - Failed to execute job 112 for task load_csv_to_postgres ([Errno 2] No such file or directory: '/opt/data/retail_clean.csv'; 684)
[2024-09-24T04:18:13.654+0000] {local_task_job_runner.py:240} INFO - Task exited with return code 1
[2024-09-24T04:18:13.776+0000] {taskinstance.py:3503} INFO - 0 downstream tasks scheduled from follow-on schedule check
[2024-09-24T04:18:13.777+0000] {local_task_job_runner.py:222} INFO - ::endgroup::
