[2024-06-25T11:41:11.301+0000] {local_task_job_runner.py:120} INFO - ::group::Pre task execution logs
[2024-06-25T11:41:11.319+0000] {taskinstance.py:2076} INFO - Dependencies all met for dep_context=non-requeueable deps ti=<TaskInstance: dag_with_postgres_operator_v01.insert_into_table manual__2024-06-25T11:35:51.818911+00:00 [queued]>
[2024-06-25T11:41:11.322+0000] {taskinstance.py:2076} INFO - Dependencies all met for dep_context=requeueable deps ti=<TaskInstance: dag_with_postgres_operator_v01.insert_into_table manual__2024-06-25T11:35:51.818911+00:00 [queued]>
[2024-06-25T11:41:11.322+0000] {taskinstance.py:2306} INFO - Starting attempt 2 of 7
[2024-06-25T11:41:11.327+0000] {taskinstance.py:2330} INFO - Executing <Task(PostgresOperator): insert_into_table> on 2024-06-25 11:35:51.818911+00:00
[2024-06-25T11:41:11.331+0000] {logging_mixin.py:188} WARNING - /home/***/.local/lib/python3.12/site-packages/***/task/task_runner/standard_task_runner.py:61 DeprecationWarning: This process (pid=20626) is multi-threaded, use of fork() may lead to deadlocks in the child.
[2024-06-25T11:41:11.332+0000] {standard_task_runner.py:63} INFO - Started process 20627 to run task
[2024-06-25T11:41:11.331+0000] {standard_task_runner.py:90} INFO - Running: ['***', 'tasks', 'run', 'dag_with_postgres_operator_v01', 'insert_into_table', 'manual__2024-06-25T11:35:51.818911+00:00', '--job-id', '39', '--raw', '--subdir', 'DAGS_FOLDER/postgres_dag.py', '--cfg-path', '/tmp/tmpog26dg5c']
[2024-06-25T11:41:11.332+0000] {standard_task_runner.py:91} INFO - Job 39: Subtask insert_into_table
[2024-06-25T11:41:11.352+0000] {task_command.py:426} INFO - Running <TaskInstance: dag_with_postgres_operator_v01.insert_into_table manual__2024-06-25T11:35:51.818911+00:00 [running]> on host 3b316f897547
[2024-06-25T11:41:11.385+0000] {taskinstance.py:2648} INFO - Exporting env vars: AIRFLOW_CTX_DAG_OWNER='jack' AIRFLOW_CTX_DAG_ID='dag_with_postgres_operator_v01' AIRFLOW_CTX_TASK_ID='insert_into_table' AIRFLOW_CTX_EXECUTION_DATE='2024-06-25T11:35:51.818911+00:00' AIRFLOW_CTX_TRY_NUMBER='2' AIRFLOW_CTX_DAG_RUN_ID='manual__2024-06-25T11:35:51.818911+00:00'
[2024-06-25T11:41:11.385+0000] {taskinstance.py:430} INFO - ::endgroup::
[2024-06-25T11:41:11.392+0000] {sql.py:276} INFO - Executing: 
            insert into Orders values(1,'pending')
        
[2024-06-25T11:41:11.396+0000] {base.py:84} INFO - Using connection ID 'postgres_localhost' for task execution.
[2024-06-25T11:41:11.401+0000] {base.py:84} INFO - Using connection ID 'postgres_localhost' for task execution.
[2024-06-25T11:41:11.408+0000] {sql.py:487} INFO - Running statement: 
            insert into Orders values(1,'pending')
        , parameters: None
[2024-06-25T11:41:11.409+0000] {taskinstance.py:441} INFO - ::group::Post task execution logs
[2024-06-25T11:41:11.409+0000] {taskinstance.py:2905} ERROR - Task failed with exception
Traceback (most recent call last):
  File "/home/airflow/.local/lib/python3.12/site-packages/airflow/models/taskinstance.py", line 465, in _execute_task
    result = _execute_callable(context=context, **execute_callable_kwargs)
             ^^^^^^^^^^^^^^^^^^^^^^^^^^^^^^^^^^^^^^^^^^^^^^^^^^^^^^^^^^^^^
  File "/home/airflow/.local/lib/python3.12/site-packages/airflow/models/taskinstance.py", line 432, in _execute_callable
    return execute_callable(context=context, **execute_callable_kwargs)
           ^^^^^^^^^^^^^^^^^^^^^^^^^^^^^^^^^^^^^^^^^^^^^^^^^^^^^^^^^^^^
  File "/home/airflow/.local/lib/python3.12/site-packages/airflow/models/baseoperator.py", line 401, in wrapper
    return func(self, *args, **kwargs)
           ^^^^^^^^^^^^^^^^^^^^^^^^^^^
  File "/home/airflow/.local/lib/python3.12/site-packages/airflow/providers/common/sql/operators/sql.py", line 282, in execute
    output = hook.run(
             ^^^^^^^^^
  File "/home/airflow/.local/lib/python3.12/site-packages/airflow/providers/common/sql/hooks/sql.py", line 435, in run
    self._run_command(cur, sql_statement, parameters)
  File "/home/airflow/.local/lib/python3.12/site-packages/airflow/providers/common/sql/hooks/sql.py", line 492, in _run_command
    cur.execute(sql_statement)
psycopg2.errors.UndefinedTable: relation "orders" does not exist
LINE 2:             insert into Orders values(1,'pending')
                                ^

[2024-06-25T11:41:11.414+0000] {taskinstance.py:1206} INFO - Marking task as UP_FOR_RETRY. dag_id=dag_with_postgres_operator_v01, task_id=insert_into_table, run_id=manual__2024-06-25T11:35:51.818911+00:00, execution_date=20240625T113551, start_date=20240625T114111, end_date=20240625T114111
[2024-06-25T11:41:11.417+0000] {standard_task_runner.py:110} ERROR - Failed to execute job 39 for task insert_into_table (relation "orders" does not exist
LINE 2:             insert into Orders values(1,'pending')
                                ^
; 20627)
[2024-06-25T11:41:11.433+0000] {local_task_job_runner.py:240} INFO - Task exited with return code 1
[2024-06-25T11:41:11.441+0000] {taskinstance.py:3503} INFO - 0 downstream tasks scheduled from follow-on schedule check
[2024-06-25T11:41:11.441+0000] {local_task_job_runner.py:222} INFO - ::endgroup::
